<?xml version="1.0"?>
<robot xmlns:xacro="http://www.ros.org/wiki/xacro" name="mobile_robot">

<!-- Base Link -->
<link name="base_link">
</link>

<xacro:property name="height" value="0.2794" /> <!-- [m] -->
<xacro:property name="width" value="0.2032" /> <!-- [m] -->
<xacro:property name="depth" value="0.0254" /> <!-- [m] -->

<!--Chassis-->
<link name="chassis">
  <visual>
   <origin xyz="0 0 0" rpy="0 0 0"/>​
    <geometry>
      <box size="${height} ${width} ${depth}"/>
    </geometry>
  </visual>
  <collision>
    <geometry>
      <box size="${height} ${width} ${depth}"/>
    </geometry>
  </collision>
  <inertial>
    <mass value="1.0"/> <!-- [kg] -->
    <inertia ixx="0.014167" ixy="0.0" ixz="0.0" iyy="0.026667" iyz="0.0" izz="0.014167"/>
  </inertial>
</link>

<gazebo reference="chassis">
  <material>Gazebo/Red</material>
</gazebo>

<joint name="chassis_joint" type="fixed">
  <parent link="base_link"/>
  <child link="chassis"/>
  <origin xyz="0 0 0"/>
</joint>

<material name="blue">
    <color rgba="0 0 0.8 1"/>
</material>

<xacro:property name="wheel_height" value="0.025" /> <!-- [m] -->
<xacro:property name="wheel_radius" value="0.0325" /> <!-- [m] -->

<!-- Wheel macro-->
<xacro:macro name="wheel" params="name reflect_x reflect_y reflect_r reflect_axis">
  
  <!-- Wheel link -->
	<link name="${name}_wheel">
    <visual>
      <geometry>
        <cylinder length="${wheel_height}" radius="${wheel_radius}"/>
      </geometry>
      <material name="blue"/>
    </visual>
    <collision>
      <geometry>
        <cylinder length="${wheel_height}" radius="${wheel_radius}"/>
      </geometry>
    </collision>
    <inertial>
      <mass value="0.1"/>  <!-- [kg] -->
      <inertia ixx="0.00031" ixy="0.0" ixz="0.0" iyy="0.00031" iyz="0.0" izz="0.00054"/>
    </inertial>
  </link>

  <!-- Wheel joint -->
  <joint name="${name}_wheel_joint" type="continuous">
    <parent link="chassis"/>
    <child link="${name}_wheel"/>
    <origin xyz="${reflect_x*height/2} ${reflect_y*(width/2+0.05)} -0.0524" rpy="${reflect_r*1.5707} 0 0"/>
    <axis xyz="0 0 ${reflect_axis}"/>
  </joint>

  <!-- Adding transmission to wheels -->
  <transmission name="${name}_wheel_trans">
    <type>transmission_interface/SimpleTransmission</type>
    <actuator name="${name}_wheel_motor">
      <mechanicalReduction>1</mechanicalReduction>
    </actuator>
    <joint name="${name}_wheel_joint">
      <hardwareInterface>hardware_interface/VelocityJointInterface</hardwareInterface>
    </joint>
  </transmission>
  
  <gazebo reference="${name}_wheel">
    <material>Gazebo/Blue</material>
  </gazebo>

</xacro:macro>

<!-- Wheels definition-->
<xacro:wheel name="front_right" reflect_x="1" reflect_y="-1" reflect_r="1" reflect_axis="-1"/>
<xacro:wheel name="front_left" reflect_x="1" reflect_y="1" reflect_r="-1" reflect_axis="1"/>
<xacro:wheel name="rear_right" reflect_x="-1" reflect_y="-1" reflect_r="1" reflect_axis="-1"/>
<xacro:wheel name="rear_left" reflect_x="-1" reflect_y="1" reflect_r="-1" reflect_axis="1"/>

<!-- nano box -->
<material name="green">
  <color rgba="0 0.8 0 1"/>
</material>

  <link name="nano">
    <visual>
      <geometry>
        <box size="0.045 0.07 0.029"/>
      </geometry>
      <material name="green"/>
    </visual>
  </link>

  <joint name="nano_joint" type="fixed">
    <parent link="chassis"/>
    <child link="nano"/>
    <origin xyz="0.0951979  -0.0170979 0.0254" rpy="0 0 0"/>
  </joint>

<gazebo reference="nano">
  <material>Gazebo/Green</material>
</gazebo>

<!--pillar box-->

 <material name="orange">
    <color rgba="1 0.3 0.1 1"/>
  </material>
<!--pillar1 box-->
 <link name="pillar1">
    <visual>
      <geometry>
        <cylinder radius="0.005" length="0.06" />
      </geometry>
      <material name="orange"/>
    </visual>
  </link>

  <joint name="pillar1_joint" type="fixed">
    <parent link="chassis"/>
    <child link="pillar1"/>
    <origin xyz="-0.100881 -0.0655712 0.0354" rpy="0 0 0"/>
  </joint>

  <gazebo reference="pillar1">
  <material>Gazebo/Orange</material>
</gazebo>


   <!--pillar2 box-->
  <link name="pillar2">
    <visual>
      <geometry>
        <cylinder radius="0.005" length="0.06" />
      </geometry>
      <material name="orange"/>
    </visual>
  </link>

  <joint name="pillar2_joint" type="fixed">
    <parent link="chassis"/>
    <child link="pillar2"/>
    <origin xyz="-0.0282339 -0.0645076 0.0354" rpy="0 0 0"/>
  </joint>


  <gazebo reference="pillar2">
  <material>Gazebo/Orange</material>
</gazebo>


    <!--pillar3 box-->
  <link name="pillar3">
    <visual>
      <geometry>
        <cylinder radius="0.005" length="0.06" />
      </geometry>
      <material name="orange"/>
    </visual>
  </link>

  <joint name="pillar3_joint" type="fixed">
    <parent link="chassis"/>
    <child link="pillar3"/>
    <origin xyz="-0.0997477 -0.0001920 0.0354" rpy="0 0 0"/>
  </joint>


  <gazebo reference="pillar3">
  <material>Gazebo/Orange</material>
</gazebo>


    <!--pillar4 box-->
  <link name="pillar4">
    <visual>
      <geometry>
        <cylinder radius="0.005" length="0.06" />
      </geometry>
      <material name="orange"/>
    </visual>
  </link>

  <joint name="pillar4_joint" type="fixed">
    <parent link="chassis"/>
    <child link="pillar4"/>
    <origin xyz="-0.0336015 -0.000379 0.0354" rpy="0 0 0"/>
  </joint>


  <gazebo reference="pillar4">
  <material>Gazebo/Orange</material>
</gazebo>

      <!--expansion box-->
  <link name="expansion">
    <visual>
      <geometry>
        <box size="0.1524 0.1016 0.0154" />
      </geometry>
      <material name="red"/>
    </visual>
  </link>

  <joint name="expansion_joint" type="fixed">
    <parent link="chassis"/>
    <child link="expansion"/>
    <origin xyz="-0.0651911 -0.0309193 0.0654" rpy="0 0 0"/>
  </joint>

   <gazebo reference="pillar4">
  <material>Gazebo/Red</material>
</gazebo>

     <!--ros box-->
  <link name="ros">
    <visual>
      <geometry>
        <box size="0.055999888 0.085000084  0.0154" />
      </geometry>
      <material name="green"/>
    </visual>
  </link>

  <joint name="ros_joint" type="fixed">
    <parent link="chassis"/>
    <child link="ros"/>
    <origin xyz="-0.0236561 -0.0258188 0.0754" rpy="0 0 0"/>
  </joint>

     <gazebo reference="pillar4">
  <material>Gazebo/Green</material>
</gazebo>


     <!--lidar box-->
  <link name="lidar">
    <visual>
      <geometry>
        <cylinder radius="0.0254" length="0.0208" />
      </geometry>
      <material name="green"/>
    </visual>
  </link>

  <joint name="lidar_joint" type="fixed">
    <parent link="chassis"/>
    <child link="lidar"/>
    <origin xyz="-0.0942216 -0.0311069 0.0754" rpy="0 0 0"/>
  </joint>

 <gazebo reference="pillar4">
  <material>Gazebo/Green</material>
</gazebo>



<!-- Link Gazebo and ROS -->
<gazebo>
  <plugin name="gazebo_ros_control" filename="libgazebo_ros_control.so">
    <robotNamespace>/</robotNamespace>
  </plugin>
</gazebo>

</robot>
